<?xml version="1.0" ?>
<robot name="trolly" xmlns:xacro="http://ros.org/wiki/xacro">

  <xacro:include filename="$(find trolly)/urdf/coloured_materials.xacro"/>
  <xacro:include filename="$(find trolly)/urdf/plugins.gazebo.xacro"/>

  <link name="base_footprint"/>




  <joint name="base_joint" type="fixed">
    <parent link="base_footprint"/>
    <child link="base_link"/>
    <origin xyz="0.0 0.0 0.010" rpy="0 0 0"/>
  </joint>

  <link name="base_link">
    <visual>
      <origin xyz="-0.064 0 0.140" rpy="0 0 0"/>
      <geometry>
        <box size="0.280 0.280 0.286"/>
      </geometry>
      <material name="orange"/>
    </visual>

    <collision>
      <origin xyz="-0.064 0 0.140" rpy="0 0 0"/>
      <geometry>
        <box size="0.280 0.280 0.286"/>
      </geometry>
    </collision>

    <inertial>
      <origin xyz="0 0 0" rpy="0 0 0"/>
      <mass value="8.2573504e-01"/>
      <inertia ixx="2.2124416e-03" ixy="-1.2294101e-05" ixz="3.4938785e-05"
               iyy="2.1193702e-03" iyz="-5.0120904e-06"
               izz="2.0064271e-03" />
    </inertial>
  </link>

  <gazebo reference="base_link">
    <material>Gazebo/Orange</material>
  </gazebo>


  <joint name="wheel_left_joint" type="continuous">
    <parent link="base_link"/>
    <child link="wheel_left_link"/>
    <origin xyz="0.0 0.16 0.046" rpy="-1.57 0 0"/>
    <axis xyz="0 0 1"/>
  </joint>

  <link name="wheel_left_link">
    <visual>
      <origin xyz="0 0 0" rpy="0 0 0"/>
      <geometry>
        <cylinder length="0.036" radius="0.066"/>
      </geometry>
      <material name="red"/>
    </visual>

    <collision>
      <origin xyz="0 0 0" rpy="0 0 0"/>
      <geometry>
        <cylinder length="0.036" radius="0.066"/>
      </geometry>
    </collision>

    <inertial>
      <origin xyz="0 0 0" />
      <mass value="2.8498940e-02" />
      <inertia ixx="1.1175580e-05" ixy="-4.2369783e-11" ixz="-5.9381719e-09"
               iyy="1.1192413e-05" iyz="-1.4400107e-11"
               izz="2.0712558e-05" />
      </inertial>
  </link>

  <gazebo reference="wheel_left_link">
    <material>Gazebo/Red</material>
  </gazebo>





  <joint name="wheel_right_joint" type="continuous">
    <parent link="base_link"/>
    <child link="wheel_right_link"/>
    <origin xyz="0.0 -0.160 0.046" rpy="-1.57 0 0"/>
    <axis xyz="0 0 1"/>
  </joint>

  <link name="wheel_right_link">
    <visual>
      <origin xyz="0 0 0" rpy="0 0 0"/>
      <geometry>
        <cylinder length="0.036" radius="0.066"/>
      </geometry>
      <material name="blue"/>
    </visual>

    <collision>
      <origin xyz="0 0 0" rpy="0 0 0"/>
      <geometry>
        <cylinder length="0.036" radius="0.066"/>
      </geometry>
    </collision>

    <inertial>
      <origin xyz="0 0 0" />
      <mass value="2.8498940e-02" />
      <inertia ixx="1.1175580e-05" ixy="-4.2369783e-11" ixz="-5.9381719e-09"
               iyy="1.1192413e-05" iyz="-1.4400107e-11"
               izz="2.0712558e-05" />
      </inertial>
  </link>

  <gazebo reference="wheel_right_link">
    <material>Gazebo/Red</material>
  </gazebo>





  <joint name="caster_back_joint" type="fixed">
    <parent link="base_link"/>
    <child link="caster_back_link"/>
    <origin xyz="-0.162 0 -0.008" rpy="-1.57 0 0"/>
  </joint>

  <link name="caster_back_link">
    <collision>
      <origin xyz="0 0.002 0" rpy="0 0 0"/>
      <geometry>
        <box size="0.060 0.018 0.040"/>
      </geometry>
    </collision>

    <inertial>
      <origin xyz="0 0 0" />
      <mass value="0.005" />
      <inertia ixx="0.001" ixy="0.0" ixz="0.0"
               iyy="0.001" iyz="0.0"
               izz="0.001" />
    </inertial>
  </link>

  <gazebo reference="caster_back_link">
    <material>Gazebo/Red</material>
  </gazebo>





  <joint name="imu_joint" type="fixed">
    <parent link="base_link"/>
    <child link="imu_link"/>
    <origin xyz="-0.064 0 0.136" rpy="0 0 0"/>
  </joint>

  <link name="imu_link"/>

  <gazebo reference="imu_link">
    <material>Gazebo/Blue</material>
  </gazebo>






  <joint name="scan_joint" type="fixed">
    <parent link="base_link"/>
    <child link="base_scan"/>
    <origin xyz="-0.064 0 0.344" rpy="0 0 0"/>
  </joint>

  <link name="base_scan">
    <visual>
      <origin xyz="0.030 0 -0.0130" rpy="0 0 0"/>
      <geometry>
        <cylinder length="0.0630" radius="0.110"/>
      </geometry>
    </visual>

    <collision>
      <origin xyz="0.030 0 -0.0130" rpy="0 0 0"/>
      <geometry>
        <cylinder length="0.0630" radius="0.110"/>
      </geometry>
    </collision>

    <inertial>
      <mass value="0.114" />
      <origin xyz="0 0 0" />
      <inertia ixx="0.001" ixy="0.0" ixz="0.0"
               iyy="0.001" iyz="0.0"
               izz="0.001" />
    </inertial>
  </link>

  <gazebo reference="base_scan">
    <material>Gazebo/Blue</material>
  </gazebo>




</robot>
